2018-11-08 09:10:56.779291
2018-11-08 09:11:06.789407
2018-11-08 09:11:16.799542
2018-11-08 09:11:26.809679
2018-11-08 09:11:36.819783
2018-11-08 09:11:46.829893
2018-11-08 09:11:56.840001
2018-11-08 09:12:06.850113
2018-11-08 09:12:16.860230
2018-11-08 09:12:26.870340
2018-11-08 09:12:36.880437
2018-11-08 09:44:39.087310
2018-11-08 09:44:49.088224
2018-11-08 09:44:59.098411
2018-11-08 09:45:09.108524
2018-11-08 09:45:19.118622
2018-11-08 09:45:29.124888
2018-11-08 09:45:39.127061
2018-11-08 09:45:49.129147
2018-11-08 09:45:59.131376
2018-11-08 09:46:09.138558
2018-11-08 09:46:19.148871
2018-11-08 09:46:29.158974
2018-11-08 09:46:39.166582
2018-11-08 09:46:49.176696
2018-11-08 09:46:59.186792
2018-11-08 09:47:09.191214
2018-11-08 09:47:19.192837
2018-11-08 09:47:29.201746
2018-11-08 09:47:39.210561
2018-11-08 09:47:49.220699
2018-11-08 09:47:59.228979
2018-11-08 09:48:09.231561
2018-11-08 09:48:19.234009
2018-11-08 09:48:29.243637
2018-11-08 09:48:39.253774
2018-11-08 09:59:20.261690
2018-11-08 09:59:30.271846
2018-11-08 09:59:40.277698
2018-11-08 09:59:50.279188
2018-11-08 10:00:00.280665
2018-11-08 10:00:10.282095
2018-11-08 10:00:20.283996
2018-11-08 10:00:30.285414
2018-11-08 10:00:40.286896
2018-11-08 10:00:50.288391
2018-11-08 10:01:00.289744
2018-11-08 10:01:10.290941
2018-11-08 10:01:20.292258
2018-11-08 10:01:30.293566
2018-11-08 10:09:38.297870
2018-11-08 10:09:48.307981
2018-11-08 10:09:58.318160
Exception ignored in: <module 'threading' from '/home/techstar/anaconda3/lib/python3.6/threading.py'>
Traceback (most recent call last):
  File "/home/techstar/anaconda3/lib/python3.6/threading.py", line 1294, in _shutdown
    t.join()
  File "/home/techstar/anaconda3/lib/python3.6/threading.py", line 1056, in join
    self._wait_for_tstate_lock()
  File "/home/techstar/anaconda3/lib/python3.6/threading.py", line 1072, in _wait_for_tstate_lock
    elif lock.acquire(block, timeout):
KeyboardInterrupt
